[Fri May 29 17:00:11.684548 2020] [wsgi:error] [pid 2601:tid 140269939148544] [remote 10.105.177.1:40536] mod_wsgi (pid=2601): Target WSGI script '/var/www/tech-iitb.org/itc_iitb/wsgi.py' cannot be loaded as Python module.
[Fri May 29 17:00:11.684655 2020] [wsgi:error] [pid 2601:tid 140269939148544] [remote 10.105.177.1:40536] mod_wsgi (pid=2601): Exception occurred processing WSGI script '/var/www/tech-iitb.org/itc_iitb/wsgi.py'.
[Fri May 29 17:00:11.758171 2020] [wsgi:error] [pid 2601:tid 140269939148544] [remote 10.105.177.1:40536] Traceback (most recent call last):
[Fri May 29 17:00:11.758260 2020] [wsgi:error] [pid 2601:tid 140269939148544] [remote 10.105.177.1:40536]   File "/var/www/tech-iitb.org/itc_iitb/wsgi.py", line 16, in <module>
[Fri May 29 17:00:11.758278 2020] [wsgi:error] [pid 2601:tid 140269939148544] [remote 10.105.177.1:40536]     application = get_wsgi_application()
[Fri May 29 17:00:11.758312 2020] [wsgi:error] [pid 2601:tid 140269939148544] [remote 10.105.177.1:40536]   File "/var/www/tech-iitb.org/.venv/lib/python3.6/site-packages/django/core/wsgi.py", line 12, in get_wsgi_application
[Fri May 29 17:00:11.758326 2020] [wsgi:error] [pid 2601:tid 140269939148544] [remote 10.105.177.1:40536]     django.setup(set_prefix=False)
[Fri May 29 17:00:11.758342 2020] [wsgi:error] [pid 2601:tid 140269939148544] [remote 10.105.177.1:40536]   File "/var/www/tech-iitb.org/.venv/lib/python3.6/site-packages/django/__init__.py", line 24, in setup
[Fri May 29 17:00:11.758363 2020] [wsgi:error] [pid 2601:tid 140269939148544] [remote 10.105.177.1:40536]     apps.populate(settings.INSTALLED_APPS)
[Fri May 29 17:00:11.758382 2020] [wsgi:error] [pid 2601:tid 140269939148544] [remote 10.105.177.1:40536]   File "/var/www/tech-iitb.org/.venv/lib/python3.6/site-packages/django/apps/registry.py", line 89, in populate
[Fri May 29 17:00:11.758402 2020] [wsgi:error] [pid 2601:tid 140269939148544] [remote 10.105.177.1:40536]     app_config = AppConfig.create(entry)
[Fri May 29 17:00:11.758420 2020] [wsgi:error] [pid 2601:tid 140269939148544] [remote 10.105.177.1:40536]   File "/var/www/tech-iitb.org/.venv/lib/python3.6/site-packages/django/apps/config.py", line 90, in create
[Fri May 29 17:00:11.758433 2020] [wsgi:error] [pid 2601:tid 140269939148544] [remote 10.105.177.1:40536]     module = import_module(entry)
[Fri May 29 17:00:11.758458 2020] [wsgi:error] [pid 2601:tid 140269939148544] [remote 10.105.177.1:40536]   File "/usr/lib/python3.6/importlib/__init__.py", line 126, in import_module
[Fri May 29 17:00:11.758471 2020] [wsgi:error] [pid 2601:tid 140269939148544] [remote 10.105.177.1:40536]     return _bootstrap._gcd_import(name[level:], package, level)
[Fri May 29 17:00:11.758487 2020] [wsgi:error] [pid 2601:tid 140269939148544] [remote 10.105.177.1:40536]   File "<frozen importlib._bootstrap>", line 994, in _gcd_import
[Fri May 29 17:00:11.758516 2020] [wsgi:error] [pid 2601:tid 140269939148544] [remote 10.105.177.1:40536]   File "<frozen importlib._bootstrap>", line 971, in _find_and_load
[Fri May 29 17:00:11.758535 2020] [wsgi:error] [pid 2601:tid 140269939148544] [remote 10.105.177.1:40536]   File "<frozen importlib._bootstrap>", line 953, in _find_and_load_unlocked
[Fri May 29 17:00:11.758566 2020] [wsgi:error] [pid 2601:tid 140269939148544] [remote 10.105.177.1:40536] ModuleNotFoundError: No module named 'import_export'
[Fri May 29 17:00:11.927410 2020] [wsgi:error] [pid 2601:tid 140269972719360] [remote 10.105.177.1:40570] mod_wsgi (pid=2601): Target WSGI script '/var/www/tech-iitb.org/itc_iitb/wsgi.py' cannot be loaded as Python module.
[Fri May 29 17:00:11.927512 2020] [wsgi:error] [pid 2601:tid 140269972719360] [remote 10.105.177.1:40570] mod_wsgi (pid=2601): Exception occurred processing WSGI script '/var/www/tech-iitb.org/itc_iitb/wsgi.py'.
[Fri May 29 17:00:11.927719 2020] [wsgi:error] [pid 2601:tid 140269972719360] [remote 10.105.177.1:40570] Traceback (most recent call last):
[Fri May 29 17:00:11.927815 2020] [wsgi:error] [pid 2601:tid 140269972719360] [remote 10.105.177.1:40570]   File "/var/www/tech-iitb.org/itc_iitb/wsgi.py", line 16, in <module>
[Fri May 29 17:00:11.927833 2020] [wsgi:error] [pid 2601:tid 140269972719360] [remote 10.105.177.1:40570]     application = get_wsgi_application()
[Fri May 29 17:00:11.927851 2020] [wsgi:error] [pid 2601:tid 140269972719360] [remote 10.105.177.1:40570]   File "/var/www/tech-iitb.org/.venv/lib/python3.6/site-packages/django/core/wsgi.py", line 12, in get_wsgi_application
[Fri May 29 17:00:11.927880 2020] [wsgi:error] [pid 2601:tid 140269972719360] [remote 10.105.177.1:40570]     django.setup(set_prefix=False)
[Fri May 29 17:00:11.927922 2020] [wsgi:error] [pid 2601:tid 140269972719360] [remote 10.105.177.1:40570]   File "/var/www/tech-iitb.org/.venv/lib/python3.6/site-packages/django/__init__.py", line 24, in setup
[Fri May 29 17:00:11.927938 2020] [wsgi:error] [pid 2601:tid 140269972719360] [remote 10.105.177.1:40570]     apps.populate(settings.INSTALLED_APPS)
[Fri May 29 17:00:11.927970 2020] [wsgi:error] [pid 2601:tid 140269972719360] [remote 10.105.177.1:40570]   File "/var/www/tech-iitb.org/.venv/lib/python3.6/site-packages/django/apps/registry.py", line 81, in populate
[Fri May 29 17:00:11.927984 2020] [wsgi:error] [pid 2601:tid 140269972719360] [remote 10.105.177.1:40570]     raise RuntimeError("populate() isn't reentrant")
[Fri May 29 17:00:11.928015 2020] [wsgi:error] [pid 2601:tid 140269972719360] [remote 10.105.177.1:40570] RuntimeError: populate() isn't reentrant
[Fri May 29 17:00:12.083218 2020] [wsgi:error] [pid 2601:tid 140269939148544] [remote 10.105.177.1:40582] mod_wsgi (pid=2601): Target WSGI script '/var/www/tech-iitb.org/itc_iitb/wsgi.py' cannot be loaded as Python module.
[Fri May 29 17:00:12.083276 2020] [wsgi:error] [pid 2601:tid 140269939148544] [remote 10.105.177.1:40582] mod_wsgi (pid=2601): Exception occurred processing WSGI script '/var/www/tech-iitb.org/itc_iitb/wsgi.py'.
[Fri May 29 17:00:12.083438 2020] [wsgi:error] [pid 2601:tid 140269939148544] [remote 10.105.177.1:40582] Traceback (most recent call last):
[Fri May 29 17:00:12.083491 2020] [wsgi:error] [pid 2601:tid 140269939148544] [remote 10.105.177.1:40582]   File "/var/www/tech-iitb.org/itc_iitb/wsgi.py", line 16, in <module>
[Fri May 29 17:00:12.083507 2020] [wsgi:error] [pid 2601:tid 140269939148544] [remote 10.105.177.1:40582]     application = get_wsgi_application()
[Fri May 29 17:00:12.083525 2020] [wsgi:error] [pid 2601:tid 140269939148544] [remote 10.105.177.1:40582]   File "/var/www/tech-iitb.org/.venv/lib/python3.6/site-packages/django/core/wsgi.py", line 12, in get_wsgi_application
[Fri May 29 17:00:12.083553 2020] [wsgi:error] [pid 2601:tid 140269939148544] [remote 10.105.177.1:40582]     django.setup(set_prefix=False)
[Fri May 29 17:00:12.083572 2020] [wsgi:error] [pid 2601:tid 140269939148544] [remote 10.105.177.1:40582]   File "/var/www/tech-iitb.org/.venv/lib/python3.6/site-packages/django/__init__.py", line 24, in setup
[Fri May 29 17:00:12.083595 2020] [wsgi:error] [pid 2601:tid 140269939148544] [remote 10.105.177.1:40582]     apps.populate(settings.INSTALLED_APPS)
[Fri May 29 17:00:12.083613 2020] [wsgi:error] [pid 2601:tid 140269939148544] [remote 10.105.177.1:40582]   File "/var/www/tech-iitb.org/.venv/lib/python3.6/site-packages/django/apps/registry.py", line 81, in populate
[Fri May 29 17:00:12.083626 2020] [wsgi:error] [pid 2601:tid 140269939148544] [remote 10.105.177.1:40582]     raise RuntimeError("populate() isn't reentrant")
[Fri May 29 17:00:12.083668 2020] [wsgi:error] [pid 2601:tid 140269939148544] [remote 10.105.177.1:40582] RuntimeError: populate() isn't reentrant
[Fri May 29 17:00:42.162376 2020] [wsgi:error] [pid 2601:tid 140269972719360] [remote 10.105.177.1:41566] mod_wsgi (pid=2601): Target WSGI script '/var/www/tech-iitb.org/itc_iitb/wsgi.py' cannot be loaded as Python module.
[Fri May 29 17:00:42.162489 2020] [wsgi:error] [pid 2601:tid 140269972719360] [remote 10.105.177.1:41566] mod_wsgi (pid=2601): Exception occurred processing WSGI script '/var/www/tech-iitb.org/itc_iitb/wsgi.py'.
[Fri May 29 17:00:42.162748 2020] [wsgi:error] [pid 2601:tid 140269972719360] [remote 10.105.177.1:41566] Traceback (most recent call last):
[Fri May 29 17:00:42.162824 2020] [wsgi:error] [pid 2601:tid 140269972719360] [remote 10.105.177.1:41566]   File "/var/www/tech-iitb.org/itc_iitb/wsgi.py", line 16, in <module>
[Fri May 29 17:00:42.162843 2020] [wsgi:error] [pid 2601:tid 140269972719360] [remote 10.105.177.1:41566]     application = get_wsgi_application()
[Fri May 29 17:00:42.162888 2020] [wsgi:error] [pid 2601:tid 140269972719360] [remote 10.105.177.1:41566]   File "/var/www/tech-iitb.org/.venv/lib/python3.6/site-packages/django/core/wsgi.py", line 12, in get_wsgi_application
[Fri May 29 17:00:42.162905 2020] [wsgi:error] [pid 2601:tid 140269972719360] [remote 10.105.177.1:41566]     django.setup(set_prefix=False)
[Fri May 29 17:00:42.162926 2020] [wsgi:error] [pid 2601:tid 140269972719360] [remote 10.105.177.1:41566]   File "/var/www/tech-iitb.org/.venv/lib/python3.6/site-packages/django/__init__.py", line 24, in setup
[Fri May 29 17:00:42.162955 2020] [wsgi:error] [pid 2601:tid 140269972719360] [remote 10.105.177.1:41566]     apps.populate(settings.INSTALLED_APPS)
[Fri May 29 17:00:42.162978 2020] [wsgi:error] [pid 2601:tid 140269972719360] [remote 10.105.177.1:41566]   File "/var/www/tech-iitb.org/.venv/lib/python3.6/site-packages/django/apps/registry.py", line 81, in populate
[Fri May 29 17:00:42.163008 2020] [wsgi:error] [pid 2601:tid 140269972719360] [remote 10.105.177.1:41566]     raise RuntimeError("populate() isn't reentrant")
[Fri May 29 17:00:42.163048 2020] [wsgi:error] [pid 2601:tid 140269972719360] [remote 10.105.177.1:41566] RuntimeError: populate() isn't reentrant
[Fri May 29 17:01:49.318192 2020] [wsgi:error] [pid 2601:tid 140269939148544] [remote 10.105.177.1:43838] mod_wsgi (pid=2601): Target WSGI script '/var/www/tech-iitb.org/itc_iitb/wsgi.py' cannot be loaded as Python module.
[Fri May 29 17:01:49.318311 2020] [wsgi:error] [pid 2601:tid 140269939148544] [remote 10.105.177.1:43838] mod_wsgi (pid=2601): Exception occurred processing WSGI script '/var/www/tech-iitb.org/itc_iitb/wsgi.py'.
[Fri May 29 17:01:49.318476 2020] [wsgi:error] [pid 2601:tid 140269939148544] [remote 10.105.177.1:43838] Traceback (most recent call last):
[Fri May 29 17:01:49.318535 2020] [wsgi:error] [pid 2601:tid 140269939148544] [remote 10.105.177.1:43838]   File "/var/www/tech-iitb.org/itc_iitb/wsgi.py", line 16, in <module>
[Fri May 29 17:01:49.318571 2020] [wsgi:error] [pid 2601:tid 140269939148544] [remote 10.105.177.1:43838]     application = get_wsgi_application()
[Fri May 29 17:01:49.318593 2020] [wsgi:error] [pid 2601:tid 140269939148544] [remote 10.105.177.1:43838]   File "/var/www/tech-iitb.org/.venv/lib/python3.6/site-packages/django/core/wsgi.py", line 12, in get_wsgi_application
[Fri May 29 17:01:49.318606 2020] [wsgi:error] [pid 2601:tid 140269939148544] [remote 10.105.177.1:43838]     django.setup(set_prefix=False)
[Fri May 29 17:01:49.318634 2020] [wsgi:error] [pid 2601:tid 140269939148544] [remote 10.105.177.1:43838]   File "/var/www/tech-iitb.org/.venv/lib/python3.6/site-packages/django/__init__.py", line 24, in setup
[Fri May 29 17:01:49.318648 2020] [wsgi:error] [pid 2601:tid 140269939148544] [remote 10.105.177.1:43838]     apps.populate(settings.INSTALLED_APPS)
[Fri May 29 17:01:49.318665 2020] [wsgi:error] [pid 2601:tid 140269939148544] [remote 10.105.177.1:43838]   File "/var/www/tech-iitb.org/.venv/lib/python3.6/site-packages/django/apps/registry.py", line 81, in populate
[Fri May 29 17:01:49.318693 2020] [wsgi:error] [pid 2601:tid 140269939148544] [remote 10.105.177.1:43838]     raise RuntimeError("populate() isn't reentrant")
[Fri May 29 17:01:49.318725 2020] [wsgi:error] [pid 2601:tid 140269939148544] [remote 10.105.177.1:43838] RuntimeError: populate() isn't reentrant
[Fri May 29 17:02:45.691128 2020] [wsgi:error] [pid 2601:tid 140269939148544] [remote 10.105.177.1:45774] mod_wsgi (pid=2601): Target WSGI script '/var/www/tech-iitb.org/itc_iitb/wsgi.py' cannot be loaded as Python module.
[Fri May 29 17:02:45.691269 2020] [wsgi:error] [pid 2601:tid 140269939148544] [remote 10.105.177.1:45774] mod_wsgi (pid=2601): Exception occurred processing WSGI script '/var/www/tech-iitb.org/itc_iitb/wsgi.py'.
[Fri May 29 17:02:45.691466 2020] [wsgi:error] [pid 2601:tid 140269939148544] [remote 10.105.177.1:45774] Traceback (most recent call last):
[Fri May 29 17:02:45.691537 2020] [wsgi:error] [pid 2601:tid 140269939148544] [remote 10.105.177.1:45774]   File "/var/www/tech-iitb.org/itc_iitb/wsgi.py", line 16, in <module>
[Fri May 29 17:02:45.691577 2020] [wsgi:error] [pid 2601:tid 140269939148544] [remote 10.105.177.1:45774]     application = get_wsgi_application()
[Fri May 29 17:02:45.691602 2020] [wsgi:error] [pid 2601:tid 140269939148544] [remote 10.105.177.1:45774]   File "/var/www/tech-iitb.org/.venv/lib/python3.6/site-packages/django/core/wsgi.py", line 12, in get_wsgi_application
[Fri May 29 17:02:45.691630 2020] [wsgi:error] [pid 2601:tid 140269939148544] [remote 10.105.177.1:45774]     django.setup(set_prefix=False)
[Fri May 29 17:02:45.691654 2020] [wsgi:error] [pid 2601:tid 140269939148544] [remote 10.105.177.1:45774]   File "/var/www/tech-iitb.org/.venv/lib/python3.6/site-packages/django/__init__.py", line 24, in setup
[Fri May 29 17:02:45.691669 2020] [wsgi:error] [pid 2601:tid 140269939148544] [remote 10.105.177.1:45774]     apps.populate(settings.INSTALLED_APPS)
[Fri May 29 17:02:45.691707 2020] [wsgi:error] [pid 2601:tid 140269939148544] [remote 10.105.177.1:45774]   File "/var/www/tech-iitb.org/.venv/lib/python3.6/site-packages/django/apps/registry.py", line 81, in populate
[Fri May 29 17:02:45.691724 2020] [wsgi:error] [pid 2601:tid 140269939148544] [remote 10.105.177.1:45774]     raise RuntimeError("populate() isn't reentrant")
[Fri May 29 17:02:45.691760 2020] [wsgi:error] [pid 2601:tid 140269939148544] [remote 10.105.177.1:45774] RuntimeError: populate() isn't reentrant
[Fri May 29 17:02:47.836565 2020] [wsgi:error] [pid 2601:tid 140269972719360] [remote 10.105.177.1:45840] mod_wsgi (pid=2601): Target WSGI script '/var/www/tech-iitb.org/itc_iitb/wsgi.py' cannot be loaded as Python module.
[Fri May 29 17:02:47.836669 2020] [wsgi:error] [pid 2601:tid 140269972719360] [remote 10.105.177.1:45840] mod_wsgi (pid=2601): Exception occurred processing WSGI script '/var/www/tech-iitb.org/itc_iitb/wsgi.py'.
[Fri May 29 17:02:47.836877 2020] [wsgi:error] [pid 2601:tid 140269972719360] [remote 10.105.177.1:45840] Traceback (most recent call last):
[Fri May 29 17:02:47.836979 2020] [wsgi:error] [pid 2601:tid 140269972719360] [remote 10.105.177.1:45840]   File "/var/www/tech-iitb.org/itc_iitb/wsgi.py", line 16, in <module>
[Fri May 29 17:02:47.836996 2020] [wsgi:error] [pid 2601:tid 140269972719360] [remote 10.105.177.1:45840]     application = get_wsgi_application()
[Fri May 29 17:02:47.837014 2020] [wsgi:error] [pid 2601:tid 140269972719360] [remote 10.105.177.1:45840]   File "/var/www/tech-iitb.org/.venv/lib/python3.6/site-packages/django/core/wsgi.py", line 12, in get_wsgi_application
[Fri May 29 17:02:47.837049 2020] [wsgi:error] [pid 2601:tid 140269972719360] [remote 10.105.177.1:45840]     django.setup(set_prefix=False)
[Fri May 29 17:02:47.837069 2020] [wsgi:error] [pid 2601:tid 140269972719360] [remote 10.105.177.1:45840]   File "/var/www/tech-iitb.org/.venv/lib/python3.6/site-packages/django/__init__.py", line 24, in setup
[Fri May 29 17:02:47.837081 2020] [wsgi:error] [pid 2601:tid 140269972719360] [remote 10.105.177.1:45840]     apps.populate(settings.INSTALLED_APPS)
[Fri May 29 17:02:47.837115 2020] [wsgi:error] [pid 2601:tid 140269972719360] [remote 10.105.177.1:45840]   File "/var/www/tech-iitb.org/.venv/lib/python3.6/site-packages/django/apps/registry.py", line 81, in populate
[Fri May 29 17:02:47.837128 2020] [wsgi:error] [pid 2601:tid 140269972719360] [remote 10.105.177.1:45840]     raise RuntimeError("populate() isn't reentrant")
[Fri May 29 17:02:47.837162 2020] [wsgi:error] [pid 2601:tid 140269972719360] [remote 10.105.177.1:45840] RuntimeError: populate() isn't reentrant
[Fri May 29 17:02:49.226507 2020] [wsgi:error] [pid 2601:tid 140269939148544] [remote 10.105.177.1:45890] mod_wsgi (pid=2601): Target WSGI script '/var/www/tech-iitb.org/itc_iitb/wsgi.py' cannot be loaded as Python module.
[Fri May 29 17:02:49.226594 2020] [wsgi:error] [pid 2601:tid 140269939148544] [remote 10.105.177.1:45890] mod_wsgi (pid=2601): Exception occurred processing WSGI script '/var/www/tech-iitb.org/itc_iitb/wsgi.py'.
[Fri May 29 17:02:49.226788 2020] [wsgi:error] [pid 2601:tid 140269939148544] [remote 10.105.177.1:45890] Traceback (most recent call last):
[Fri May 29 17:02:49.226849 2020] [wsgi:error] [pid 2601:tid 140269939148544] [remote 10.105.177.1:45890]   File "/var/www/tech-iitb.org/itc_iitb/wsgi.py", line 16, in <module>
[Fri May 29 17:02:49.226865 2020] [wsgi:error] [pid 2601:tid 140269939148544] [remote 10.105.177.1:45890]     application = get_wsgi_application()
[Fri May 29 17:02:49.226883 2020] [wsgi:error] [pid 2601:tid 140269939148544] [remote 10.105.177.1:45890]   File "/var/www/tech-iitb.org/.venv/lib/python3.6/site-packages/django/core/wsgi.py", line 12, in get_wsgi_application
[Fri May 29 17:02:49.226912 2020] [wsgi:error] [pid 2601:tid 140269939148544] [remote 10.105.177.1:45890]     django.setup(set_prefix=False)
[Fri May 29 17:02:49.226933 2020] [wsgi:error] [pid 2601:tid 140269939148544] [remote 10.105.177.1:45890]   File "/var/www/tech-iitb.org/.venv/lib/python3.6/site-packages/django/__init__.py", line 24, in setup
[Fri May 29 17:02:49.226957 2020] [wsgi:error] [pid 2601:tid 140269939148544] [remote 10.105.177.1:45890]     apps.populate(settings.INSTALLED_APPS)
[Fri May 29 17:02:49.226976 2020] [wsgi:error] [pid 2601:tid 140269939148544] [remote 10.105.177.1:45890]   File "/var/www/tech-iitb.org/.venv/lib/python3.6/site-packages/django/apps/registry.py", line 81, in populate
[Fri May 29 17:02:49.226989 2020] [wsgi:error] [pid 2601:tid 140269939148544] [remote 10.105.177.1:45890]     raise RuntimeError("populate() isn't reentrant")
[Fri May 29 17:02:49.227032 2020] [wsgi:error] [pid 2601:tid 140269939148544] [remote 10.105.177.1:45890] RuntimeError: populate() isn't reentrant
[Fri May 29 17:02:49.596367 2020] [wsgi:error] [pid 2601:tid 140269972719360] [remote 10.105.177.1:45896] mod_wsgi (pid=2601): Target WSGI script '/var/www/tech-iitb.org/itc_iitb/wsgi.py' cannot be loaded as Python module.
[Fri May 29 17:02:49.596456 2020] [wsgi:error] [pid 2601:tid 140269972719360] [remote 10.105.177.1:45896] mod_wsgi (pid=2601): Exception occurred processing WSGI script '/var/www/tech-iitb.org/itc_iitb/wsgi.py'.
[Fri May 29 17:02:49.596698 2020] [wsgi:error] [pid 2601:tid 140269972719360] [remote 10.105.177.1:45896] Traceback (most recent call last):
[Fri May 29 17:02:49.596764 2020] [wsgi:error] [pid 2601:tid 140269972719360] [remote 10.105.177.1:45896]   File "/var/www/tech-iitb.org/itc_iitb/wsgi.py", line 16, in <module>
[Fri May 29 17:02:49.596780 2020] [wsgi:error] [pid 2601:tid 140269972719360] [remote 10.105.177.1:45896]     application = get_wsgi_application()
[Fri May 29 17:02:49.596830 2020] [wsgi:error] [pid 2601:tid 140269972719360] [remote 10.105.177.1:45896]   File "/var/www/tech-iitb.org/.venv/lib/python3.6/site-packages/django/core/wsgi.py", line 12, in get_wsgi_application
[Fri May 29 17:02:49.596848 2020] [wsgi:error] [pid 2601:tid 140269972719360] [remote 10.105.177.1:45896]     django.setup(set_prefix=False)
[Fri May 29 17:02:49.596865 2020] [wsgi:error] [pid 2601:tid 140269972719360] [remote 10.105.177.1:45896]   File "/var/www/tech-iitb.org/.venv/lib/python3.6/site-packages/django/__init__.py", line 24, in setup
[Fri May 29 17:02:49.596897 2020] [wsgi:error] [pid 2601:tid 140269972719360] [remote 10.105.177.1:45896]     apps.populate(settings.INSTALLED_APPS)
[Fri May 29 17:02:49.596918 2020] [wsgi:error] [pid 2601:tid 140269972719360] [remote 10.105.177.1:45896]   File "/var/www/tech-iitb.org/.venv/lib/python3.6/site-packages/django/apps/registry.py", line 81, in populate
[Fri May 29 17:02:49.596962 2020] [wsgi:error] [pid 2601:tid 140269972719360] [remote 10.105.177.1:45896]     raise RuntimeError("populate() isn't reentrant")
[Fri May 29 17:02:49.596999 2020] [wsgi:error] [pid 2601:tid 140269972719360] [remote 10.105.177.1:45896] RuntimeError: populate() isn't reentrant
[Fri May 29 17:02:49.970151 2020] [wsgi:error] [pid 2601:tid 140269939148544] [remote 10.105.177.1:45940] mod_wsgi (pid=2601): Target WSGI script '/var/www/tech-iitb.org/itc_iitb/wsgi.py' cannot be loaded as Python module.
[Fri May 29 17:02:49.970265 2020] [wsgi:error] [pid 2601:tid 140269939148544] [remote 10.105.177.1:45940] mod_wsgi (pid=2601): Exception occurred processing WSGI script '/var/www/tech-iitb.org/itc_iitb/wsgi.py'.
[Fri May 29 17:02:49.970433 2020] [wsgi:error] [pid 2601:tid 140269939148544] [remote 10.105.177.1:45940] Traceback (most recent call last):
[Fri May 29 17:02:49.970492 2020] [wsgi:error] [pid 2601:tid 140269939148544] [remote 10.105.177.1:45940]   File "/var/www/tech-iitb.org/itc_iitb/wsgi.py", line 16, in <module>
[Fri May 29 17:02:49.970540 2020] [wsgi:error] [pid 2601:tid 140269939148544] [remote 10.105.177.1:45940]     application = get_wsgi_application()
[Fri May 29 17:02:49.970563 2020] [wsgi:error] [pid 2601:tid 140269939148544] [remote 10.105.177.1:45940]   File "/var/www/tech-iitb.org/.venv/lib/python3.6/site-packages/django/core/wsgi.py", line 12, in get_wsgi_application
[Fri May 29 17:02:49.970577 2020] [wsgi:error] [pid 2601:tid 140269939148544] [remote 10.105.177.1:45940]     django.setup(set_prefix=False)
[Fri May 29 17:02:49.970621 2020] [wsgi:error] [pid 2601:tid 140269939148544] [remote 10.105.177.1:45940]   File "/var/www/tech-iitb.org/.venv/lib/python3.6/site-packages/django/__init__.py", line 24, in setup
[Fri May 29 17:02:49.970636 2020] [wsgi:error] [pid 2601:tid 140269939148544] [remote 10.105.177.1:45940]     apps.populate(settings.INSTALLED_APPS)
[Fri May 29 17:02:49.970653 2020] [wsgi:error] [pid 2601:tid 140269939148544] [remote 10.105.177.1:45940]   File "/var/www/tech-iitb.org/.venv/lib/python3.6/site-packages/django/apps/registry.py", line 81, in populate
[Fri May 29 17:02:49.970678 2020] [wsgi:error] [pid 2601:tid 140269939148544] [remote 10.105.177.1:45940]     raise RuntimeError("populate() isn't reentrant")
[Fri May 29 17:02:49.970712 2020] [wsgi:error] [pid 2601:tid 140269939148544] [remote 10.105.177.1:45940] RuntimeError: populate() isn't reentrant
[Fri May 29 17:02:50.408237 2020] [wsgi:error] [pid 2601:tid 140269972719360] [remote 10.105.177.1:45946] mod_wsgi (pid=2601): Target WSGI script '/var/www/tech-iitb.org/itc_iitb/wsgi.py' cannot be loaded as Python module.
[Fri May 29 17:02:50.408362 2020] [wsgi:error] [pid 2601:tid 140269972719360] [remote 10.105.177.1:45946] mod_wsgi (pid=2601): Exception occurred processing WSGI script '/var/www/tech-iitb.org/itc_iitb/wsgi.py'.
[Fri May 29 17:02:50.408541 2020] [wsgi:error] [pid 2601:tid 140269972719360] [remote 10.105.177.1:45946] Traceback (most recent call last):
[Fri May 29 17:02:50.408602 2020] [wsgi:error] [pid 2601:tid 140269972719360] [remote 10.105.177.1:45946]   File "/var/www/tech-iitb.org/itc_iitb/wsgi.py", line 16, in <module>
[Fri May 29 17:02:50.408634 2020] [wsgi:error] [pid 2601:tid 140269972719360] [remote 10.105.177.1:45946]     application = get_wsgi_application()
[Fri May 29 17:02:50.408655 2020] [wsgi:error] [pid 2601:tid 140269972719360] [remote 10.105.177.1:45946]   File "/var/www/tech-iitb.org/.venv/lib/python3.6/site-packages/django/core/wsgi.py", line 12, in get_wsgi_application
[Fri May 29 17:02:50.408688 2020] [wsgi:error] [pid 2601:tid 140269972719360] [remote 10.105.177.1:45946]     django.setup(set_prefix=False)
[Fri May 29 17:02:50.408707 2020] [wsgi:error] [pid 2601:tid 140269972719360] [remote 10.105.177.1:45946]   File "/var/www/tech-iitb.org/.venv/lib/python3.6/site-packages/django/__init__.py", line 24, in setup
[Fri May 29 17:02:50.408720 2020] [wsgi:error] [pid 2601:tid 140269972719360] [remote 10.105.177.1:45946]     apps.populate(settings.INSTALLED_APPS)
[Fri May 29 17:02:50.408757 2020] [wsgi:error] [pid 2601:tid 140269972719360] [remote 10.105.177.1:45946]   File "/var/www/tech-iitb.org/.venv/lib/python3.6/site-packages/django/apps/registry.py", line 81, in populate
[Fri May 29 17:02:50.408771 2020] [wsgi:error] [pid 2601:tid 140269972719360] [remote 10.105.177.1:45946]     raise RuntimeError("populate() isn't reentrant")
[Fri May 29 17:02:50.408802 2020] [wsgi:error] [pid 2601:tid 140269972719360] [remote 10.105.177.1:45946] RuntimeError: populate() isn't reentrant
[Fri May 29 17:02:50.460222 2020] [wsgi:error] [pid 2601:tid 140269939148544] [remote 10.105.177.1:45950] mod_wsgi (pid=2601): Target WSGI script '/var/www/tech-iitb.org/itc_iitb/wsgi.py' cannot be loaded as Python module.
[Fri May 29 17:02:50.460289 2020] [wsgi:error] [pid 2601:tid 140269939148544] [remote 10.105.177.1:45950] mod_wsgi (pid=2601): Exception occurred processing WSGI script '/var/www/tech-iitb.org/itc_iitb/wsgi.py'.
[Fri May 29 17:02:50.460432 2020] [wsgi:error] [pid 2601:tid 140269939148544] [remote 10.105.177.1:45950] Traceback (most recent call last):
[Fri May 29 17:02:50.460521 2020] [wsgi:error] [pid 2601:tid 140269939148544] [remote 10.105.177.1:45950]   File "/var/www/tech-iitb.org/itc_iitb/wsgi.py", line 16, in <module>
[Fri May 29 17:02:50.460538 2020] [wsgi:error] [pid 2601:tid 140269939148544] [remote 10.105.177.1:45950]     application = get_wsgi_application()
[Fri May 29 17:02:50.460555 2020] [wsgi:error] [pid 2601:tid 140269939148544] [remote 10.105.177.1:45950]   File "/var/www/tech-iitb.org/.venv/lib/python3.6/site-packages/django/core/wsgi.py", line 12, in get_wsgi_application
[Fri May 29 17:02:50.460587 2020] [wsgi:error] [pid 2601:tid 140269939148544] [remote 10.105.177.1:45950]     django.setup(set_prefix=False)
[Fri May 29 17:02:50.460607 2020] [wsgi:error] [pid 2601:tid 140269939148544] [remote 10.105.177.1:45950]   File "/var/www/tech-iitb.org/.venv/lib/python3.6/site-packages/django/__init__.py", line 24, in setup
[Fri May 29 17:02:50.460619 2020] [wsgi:error] [pid 2601:tid 140269939148544] [remote 10.105.177.1:45950]     apps.populate(settings.INSTALLED_APPS)
[Fri May 29 17:02:50.460649 2020] [wsgi:error] [pid 2601:tid 140269939148544] [remote 10.105.177.1:45950]   File "/var/www/tech-iitb.org/.venv/lib/python3.6/site-packages/django/apps/registry.py", line 81, in populate
[Fri May 29 17:02:50.460662 2020] [wsgi:error] [pid 2601:tid 140269939148544] [remote 10.105.177.1:45950]     raise RuntimeError("populate() isn't reentrant")
[Fri May 29 17:02:50.460690 2020] [wsgi:error] [pid 2601:tid 140269939148544] [remote 10.105.177.1:45950] RuntimeError: populate() isn't reentrant
[Fri May 29 17:02:50.988201 2020] [wsgi:error] [pid 2601:tid 140269972719360] [remote 10.105.177.1:45978] mod_wsgi (pid=2601): Target WSGI script '/var/www/tech-iitb.org/itc_iitb/wsgi.py' cannot be loaded as Python module.
[Fri May 29 17:02:50.988274 2020] [wsgi:error] [pid 2601:tid 140269972719360] [remote 10.105.177.1:45978] mod_wsgi (pid=2601): Exception occurred processing WSGI script '/var/www/tech-iitb.org/itc_iitb/wsgi.py'.
[Fri May 29 17:02:50.988508 2020] [wsgi:error] [pid 2601:tid 140269972719360] [remote 10.105.177.1:45978] Traceback (most recent call last):
[Fri May 29 17:02:50.988579 2020] [wsgi:error] [pid 2601:tid 140269972719360] [remote 10.105.177.1:45978]   File "/var/www/tech-iitb.org/itc_iitb/wsgi.py", line 16, in <module>
[Fri May 29 17:02:50.988598 2020] [wsgi:error] [pid 2601:tid 140269972719360] [remote 10.105.177.1:45978]     application = get_wsgi_application()
[Fri May 29 17:02:50.988620 2020] [wsgi:error] [pid 2601:tid 140269972719360] [remote 10.105.177.1:45978]   File "/var/www/tech-iitb.org/.venv/lib/python3.6/site-packages/django/core/wsgi.py", line 12, in get_wsgi_application
[Fri May 29 17:02:50.988667 2020] [wsgi:error] [pid 2601:tid 140269972719360] [remote 10.105.177.1:45978]     django.setup(set_prefix=False)
[Fri May 29 17:02:50.988692 2020] [wsgi:error] [pid 2601:tid 140269972719360] [remote 10.105.177.1:45978]   File "/var/www/tech-iitb.org/.venv/lib/python3.6/site-packages/django/__init__.py", line 24, in setup
[Fri May 29 17:02:50.988734 2020] [wsgi:error] [pid 2601:tid 140269972719360] [remote 10.105.177.1:45978]     apps.populate(settings.INSTALLED_APPS)
[Fri May 29 17:02:50.988758 2020] [wsgi:error] [pid 2601:tid 140269972719360] [remote 10.105.177.1:45978]   File "/var/www/tech-iitb.org/.venv/lib/python3.6/site-packages/django/apps/registry.py", line 81, in populate
[Fri May 29 17:02:50.988774 2020] [wsgi:error] [pid 2601:tid 140269972719360] [remote 10.105.177.1:45978]     raise RuntimeError("populate() isn't reentrant")
[Fri May 29 17:02:50.988828 2020] [wsgi:error] [pid 2601:tid 140269972719360] [remote 10.105.177.1:45978] RuntimeError: populate() isn't reentrant
[Fri May 29 17:02:51.492439 2020] [wsgi:error] [pid 2601:tid 140269939148544] [remote 10.105.177.1:45996] mod_wsgi (pid=2601): Target WSGI script '/var/www/tech-iitb.org/itc_iitb/wsgi.py' cannot be loaded as Python module.
[Fri May 29 17:02:51.492529 2020] [wsgi:error] [pid 2601:tid 140269939148544] [remote 10.105.177.1:45996] mod_wsgi (pid=2601): Exception occurred processing WSGI script '/var/www/tech-iitb.org/itc_iitb/wsgi.py'.
[Fri May 29 17:02:51.492807 2020] [wsgi:error] [pid 2601:tid 140269939148544] [remote 10.105.177.1:45996] Traceback (most recent call last):
[Fri May 29 17:02:51.492881 2020] [wsgi:error] [pid 2601:tid 140269939148544] [remote 10.105.177.1:45996]   File "/var/www/tech-iitb.org/itc_iitb/wsgi.py", line 16, in <module>
[Fri May 29 17:02:51.492900 2020] [wsgi:error] [pid 2601:tid 140269939148544] [remote 10.105.177.1:45996]     application = get_wsgi_application()
[Fri May 29 17:02:51.492951 2020] [wsgi:error] [pid 2601:tid 140269939148544] [remote 10.105.177.1:45996]   File "/var/www/tech-iitb.org/.venv/lib/python3.6/site-packages/django/core/wsgi.py", line 12, in get_wsgi_application
[Fri May 29 17:02:51.492969 2020] [wsgi:error] [pid 2601:tid 140269939148544] [remote 10.105.177.1:45996]     django.setup(set_prefix=False)
[Fri May 29 17:02:51.492991 2020] [wsgi:error] [pid 2601:tid 140269939148544] [remote 10.105.177.1:45996]   File "/var/www/tech-iitb.org/.venv/lib/python3.6/site-packages/django/__init__.py", line 24, in setup
[Fri May 29 17:02:51.493023 2020] [wsgi:error] [pid 2601:tid 140269939148544] [remote 10.105.177.1:45996]     apps.populate(settings.INSTALLED_APPS)
[Fri May 29 17:02:51.493046 2020] [wsgi:error] [pid 2601:tid 140269939148544] [remote 10.105.177.1:45996]   File "/var/www/tech-iitb.org/.venv/lib/python3.6/site-packages/django/apps/registry.py", line 81, in populate
[Fri May 29 17:02:51.493077 2020] [wsgi:error] [pid 2601:tid 140269939148544] [remote 10.105.177.1:45996]     raise RuntimeError("populate() isn't reentrant")
[Fri May 29 17:02:51.493116 2020] [wsgi:error] [pid 2601:tid 140269939148544] [remote 10.105.177.1:45996] RuntimeError: populate() isn't reentrant
[Fri May 29 17:02:52.062763 2020] [wsgi:error] [pid 2601:tid 140269972719360] [remote 10.105.177.1:46034] mod_wsgi (pid=2601): Target WSGI script '/var/www/tech-iitb.org/itc_iitb/wsgi.py' cannot be loaded as Python module.
[Fri May 29 17:02:52.062909 2020] [wsgi:error] [pid 2601:tid 140269972719360] [remote 10.105.177.1:46034] mod_wsgi (pid=2601): Exception occurred processing WSGI script '/var/www/tech-iitb.org/itc_iitb/wsgi.py'.
[Fri May 29 17:02:52.063122 2020] [wsgi:error] [pid 2601:tid 140269972719360] [remote 10.105.177.1:46034] Traceback (most recent call last):
[Fri May 29 17:02:52.063186 2020] [wsgi:error] [pid 2601:tid 140269972719360] [remote 10.105.177.1:46034]   File "/var/www/tech-iitb.org/itc_iitb/wsgi.py", line 16, in <module>
[Fri May 29 17:02:52.063243 2020] [wsgi:error] [pid 2601:tid 140269972719360] [remote 10.105.177.1:46034]     application = get_wsgi_application()
[Fri May 29 17:02:52.063266 2020] [wsgi:error] [pid 2601:tid 140269972719360] [remote 10.105.177.1:46034]   File "/var/www/tech-iitb.org/.venv/lib/python3.6/site-packages/django/core/wsgi.py", line 12, in get_wsgi_application
[Fri May 29 17:02:52.063279 2020] [wsgi:error] [pid 2601:tid 140269972719360] [remote 10.105.177.1:46034]     django.setup(set_prefix=False)
[Fri May 29 17:02:52.063317 2020] [wsgi:error] [pid 2601:tid 140269972719360] [remote 10.105.177.1:46034]   File "/var/www/tech-iitb.org/.venv/lib/python3.6/site-packages/django/__init__.py", line 24, in setup
[Fri May 29 17:02:52.063330 2020] [wsgi:error] [pid 2601:tid 140269972719360] [remote 10.105.177.1:46034]     apps.populate(settings.INSTALLED_APPS)
[Fri May 29 17:02:52.063346 2020] [wsgi:error] [pid 2601:tid 140269972719360] [remote 10.105.177.1:46034]   File "/var/www/tech-iitb.org/.venv/lib/python3.6/site-packages/django/apps/registry.py", line 81, in populate
[Fri May 29 17:02:52.063372 2020] [wsgi:error] [pid 2601:tid 140269972719360] [remote 10.105.177.1:46034]     raise RuntimeError("populate() isn't reentrant")
[Fri May 29 17:02:52.063406 2020] [wsgi:error] [pid 2601:tid 140269972719360] [remote 10.105.177.1:46034] RuntimeError: populate() isn't reentrant
[Fri May 29 17:02:52.428507 2020] [wsgi:error] [pid 2601:tid 140269939148544] [remote 10.105.177.1:46042] mod_wsgi (pid=2601): Target WSGI script '/var/www/tech-iitb.org/itc_iitb/wsgi.py' cannot be loaded as Python module.
[Fri May 29 17:02:52.428616 2020] [wsgi:error] [pid 2601:tid 140269939148544] [remote 10.105.177.1:46042] mod_wsgi (pid=2601): Exception occurred processing WSGI script '/var/www/tech-iitb.org/itc_iitb/wsgi.py'.
[Fri May 29 17:02:52.428772 2020] [wsgi:error] [pid 2601:tid 140269939148544] [remote 10.105.177.1:46042] Traceback (most recent call last):
[Fri May 29 17:02:52.428830 2020] [wsgi:error] [pid 2601:tid 140269939148544] [remote 10.105.177.1:46042]   File "/var/www/tech-iitb.org/itc_iitb/wsgi.py", line 16, in <module>
[Fri May 29 17:02:52.428865 2020] [wsgi:error] [pid 2601:tid 140269939148544] [remote 10.105.177.1:46042]     application = get_wsgi_application()
[Fri May 29 17:02:52.428886 2020] [wsgi:error] [pid 2601:tid 140269939148544] [remote 10.105.177.1:46042]   File "/var/www/tech-iitb.org/.venv/lib/python3.6/site-packages/django/core/wsgi.py", line 12, in get_wsgi_application
[Fri May 29 17:02:52.428913 2020] [wsgi:error] [pid 2601:tid 140269939148544] [remote 10.105.177.1:46042]     django.setup(set_prefix=False)
[Fri May 29 17:02:52.428932 2020] [wsgi:error] [pid 2601:tid 140269939148544] [remote 10.105.177.1:46042]   File "/var/www/tech-iitb.org/.venv/lib/python3.6/site-packages/django/__init__.py", line 24, in setup
[Fri May 29 17:02:52.428945 2020] [wsgi:error] [pid 2601:tid 140269939148544] [remote 10.105.177.1:46042]     apps.populate(settings.INSTALLED_APPS)
[Fri May 29 17:02:52.428975 2020] [wsgi:error] [pid 2601:tid 140269939148544] [remote 10.105.177.1:46042]   File "/var/www/tech-iitb.org/.venv/lib/python3.6/site-packages/django/apps/registry.py", line 81, in populate
[Fri May 29 17:02:52.428989 2020] [wsgi:error] [pid 2601:tid 140269939148544] [remote 10.105.177.1:46042]     raise RuntimeError("populate() isn't reentrant")
[Fri May 29 17:02:52.429018 2020] [wsgi:error] [pid 2601:tid 140269939148544] [remote 10.105.177.1:46042] RuntimeError: populate() isn't reentrant
[Fri May 29 17:02:52.796547 2020] [wsgi:error] [pid 2601:tid 140269972719360] [remote 10.105.177.1:46068] mod_wsgi (pid=2601): Target WSGI script '/var/www/tech-iitb.org/itc_iitb/wsgi.py' cannot be loaded as Python module.
[Fri May 29 17:02:52.796628 2020] [wsgi:error] [pid 2601:tid 140269972719360] [remote 10.105.177.1:46068] mod_wsgi (pid=2601): Exception occurred processing WSGI script '/var/www/tech-iitb.org/itc_iitb/wsgi.py'.
[Fri May 29 17:02:52.796818 2020] [wsgi:error] [pid 2601:tid 140269972719360] [remote 10.105.177.1:46068] Traceback (most recent call last):
[Fri May 29 17:02:52.796917 2020] [wsgi:error] [pid 2601:tid 140269972719360] [remote 10.105.177.1:46068]   File "/var/www/tech-iitb.org/itc_iitb/wsgi.py", line 16, in <module>
[Fri May 29 17:02:52.796935 2020] [wsgi:error] [pid 2601:tid 140269972719360] [remote 10.105.177.1:46068]     application = get_wsgi_application()
[Fri May 29 17:02:52.796953 2020] [wsgi:error] [pid 2601:tid 140269972719360] [remote 10.105.177.1:46068]   File "/var/www/tech-iitb.org/.venv/lib/python3.6/site-packages/django/core/wsgi.py", line 12, in get_wsgi_application
[Fri May 29 17:02:52.796985 2020] [wsgi:error] [pid 2601:tid 140269972719360] [remote 10.105.177.1:46068]     django.setup(set_prefix=False)
[Fri May 29 17:02:52.797005 2020] [wsgi:error] [pid 2601:tid 140269972719360] [remote 10.105.177.1:46068]   File "/var/www/tech-iitb.org/.venv/lib/python3.6/site-packages/django/__init__.py", line 24, in setup
[Fri May 29 17:02:52.797018 2020] [wsgi:error] [pid 2601:tid 140269972719360] [remote 10.105.177.1:46068]     apps.populate(settings.INSTALLED_APPS)
[Fri May 29 17:02:52.797050 2020] [wsgi:error] [pid 2601:tid 140269972719360] [remote 10.105.177.1:46068]   File "/var/www/tech-iitb.org/.venv/lib/python3.6/site-packages/django/apps/registry.py", line 81, in populate
[Fri May 29 17:02:52.797065 2020] [wsgi:error] [pid 2601:tid 140269972719360] [remote 10.105.177.1:46068]     raise RuntimeError("populate() isn't reentrant")
[Fri May 29 17:02:52.797097 2020] [wsgi:error] [pid 2601:tid 140269972719360] [remote 10.105.177.1:46068] RuntimeError: populate() isn't reentrant